Workbook

Sheet Read me
A1: 5U AI - Competitor Analysis
A2: Compiled 30 July 2026
A5: SCOPE | B5: 26 companies across the EU, UK and US, plus Israel and Australia where a vendor materially sells into those markets. Selection covers four archetypes: agentic AI workers (direct), US freight-brokerage AI agents (same technology, adjacent buyer), point solutions (documents, quoting, visibility), and incumbents that shape the buying decision.
A6: METHOD | B6: Desk research on 30 July 2026: vendor websites and legal documents, published pricing pages, funding announcements and trade press, plus vendor job specifications, which repeatedly disclosed more about traction and delivery model than the marketing pages did.
A7: HOW TO READ | B7: 'Competitor master' profiles every company. 'Feature matrix' scores product coverage. 'Pricing' is the commercial picture. 'GTM and ICP' covers how each competitor sells and to whom. 'Vs 5U AI' is the head-to-head read with a threat level. 'Horizontal platforms' covers the build-it-ourselves objection (Copilot Studio, n8n, UiPath, DIY). 'Pricing benchmarks' holds reference data. 'Pricing recommendation' proposes a rate card with a live ROI model. 'Market sizing' sizes TAM, SAM and SOM two ways. 'Whitespace' maps the seven uncovered spaces. 'Unit economics' tests the rate card from the seller's side. Every claim traces to 'Sources'.
A8: CONFIDENCE | B8: Cells reading 'Unknown' or 'Not disclosed' mean exactly that - no public source was found. They are not zeros and should not be read as gaps in the competitor's product. Feature scores for private companies are inferred from vendor marketing and press coverage, so treat them as directional.
A10: HEADLINE FINDINGS
A11: 1. Pricing opacity is near-total | B11: Only 2 of 26 vendors publish list prices: Quotiss (from US$69/user/month) and Freightos Terminal (US$119-239/month). Every agentic AI vendor - without exception - is sales-led and bespoke. 5U AI is following category norms, not hiding something unusual.
A12: 2. The pricing model is shifting under the category | B12: HappyRobot prices per action, Expedock explicitly refuses per-document fees, and the wider AI-agent market moved to hybrid base-plus-usage (41% adoption) while per-seat fell from 21% to 15% in a year. 5U AI's bespoke annual Order Form with a 2-year lock-in is the most old-fashioned commercial structure in the peer set.
A13: 3. The dangerous competitor is Nexcade, not the US giants | B13: London-based, same product thesis, same buyer, announced US$6m three weeks before 5U AI's round, and already lists XPO and Zencargo. Its founder was COO of Sedna, so distribution into forwarding is not a cold start.
A14: 4. Cargofy is an order of magnitude ahead commercially | B14: US$10m+ ARR and 2,000 paying customers against 5U AI's sub-EUR 1m. Different primary buyer today (carriers and dispatch rather than forwarders), which is the main thing keeping them apart.
A15: 5. Capital is not the constraint - focus is | B15: US$62m (HappyRobot), US$85m (Augment) and US$47.7m (Raft) dwarf 5U AI's US$3.2m. None of them currently sell EU forwarding as their core motion. That gap is 5U AI's entire opportunity, and it is time-limited.
A16: 6. The real price anchor is not another AI vendor | B16: It is Quotiss at US$69/user/month and CargoWise bundling a rate module into an existing licence. A forwarder who has seen those numbers will need a very concrete ROI story to sign a five-figure two-year commitment.
A18: COVERAGE BY REGION
A19: EU | B19: =COUNTIF('Competitor master'!$D$4:$D$100,"EU") -> 8
A20: UK | B20: =COUNTIF('Competitor master'!$D$4:$D$100,"UK") -> 4
A21: US | B21: =COUNTIF('Competitor master'!$D$4:$D$100,"US") -> 12
A22: Other / global | B22: =COUNTIF('Competitor master'!$D$4:$D$100,"Other*") -> 3
A23: Total profiled | B23: =COUNTA('Competitor master'!$A$4:$A$100) -> 27

Sheet Competitor master
A1: Competitor master
A2: 5U AI highlighted. 'n/a' = not disclosed publicly.
A3: Company | B3: HQ | C3: Country | D3: Region | E3: Founded | F3: Stage | G3: Total raised (US$m) | H3: Last / largest round | I3: Key investors | J3: Archetype | K3: Primary buyer | L3: Modes | M3: Core product | N3: Key differentiator | O3: Headcount | P3: Named customers | Q3: Traction signals | R3: Website
A4: 5U AI | B4: Munich (entity: Rotterdam) | C4: Germany / Netherlands | D4: EU | E4: 2025 | F4: Pre-seed | G4: 3.2 | H4: US$3.2m pre-seed, 28 Jul 2026, led by Emerge Capital | I4: Emerge Capital (lead), Inari, angels incl. ex-DHL / GEODIS / DSV / Maersk / CEVA operators | J4: Agentic AI workers | K4: Mid-sized freight forwarders, 100-500 employees | L4: Air, Ocean, Road | M4: Configurable AI Workers living in email, chat and TMS; SOP-driven, human-in-the-loop, executed end to end | N4: Context / Decision Layer: records the reasoning behind every operational decision, not just the action | O4: 7 (+7 open roles) | P4: TCI International Logistics | Q4: Paying customers in DE, AT and Benelux that renew and expand; scaling toward EUR MM ARR (implies <EUR 1m today); zero marketing spend | R4: 5u.ai
A5: Nexcade | B5: London | C5: United Kingdom | D5: UK | E5: 2025 | F5: Seed | G5: 8.5 | H5: US$6m seed, 8 Jul 2026, led by Project A Ventures (US$2.5m pre-seed prior) | I5: Project A Ventures (lead), Connect Ventures, MMC Ventures, Entropy Industrial Capital; angels from Vanguard Logistics, n8n, Altana, Sedna, UiPath, Cleo | J5: Agentic AI workers | K5: Freight forwarders | L5: Air, Ocean, Road | M5: Job-specific AI agents that read customer emails, attachments and spreadsheets to prepare quotations, procure rates and enter shipment orders | N5: Agents scoped to a single forwarding job and tuned per customer; final decisions deliberately left with human operators | O5: n/a | P5: XPO, Zencargo, Cardinal Global Logistics, CargoTrans | Q5: Named enterprise logos at seed stage; founded by ex-Sedna COO Dan Bailey and ex-Palantir tech lead Tasho Kjosev | R5: nexcade.ai
A6: Cargofy | B6: Kyiv / pan-EU + US | C6: Ukraine | D6: EU | E6: n/a | F6: Series A | G6: 11.0 | H6: US$11m Series A, Jun 2026 (US$6m primary + US$5m secondary), ~EUR 9.6m | I6: u.ventures, Toloka, Movens Capital (co-leads); angel Des Traynor (Intercom co-founder) | J6: Agentic AI workers | K6: Carriers, brokers, dispatch teams, freight ops | L6: Road-heavy, multi-modal | M6: AI digital workers that mirror human freight staff workflows; connects to 70+ existing tools incl. TMS, ERP, load boards, carrier compliance | N6: Scale and integration breadth; the revenue leader among AI-worker startups in this category | O6: n/a | P6: Not disclosed publicly (315-truck fleet deployment cited) | Q6: US$10m+ ARR and 2,000 paying customers across Europe, US and Caspian; one 315-truck deployment saving ~EUR 72,400/month | R6: cargofy.com
A7: Raft (fka Vector.ai) | B7: London | C7: United Kingdom | D7: UK | E7: 2017 | F7: Series B | G7: 47.7 | H7: US$30m Series B, Jul 2023, led by Eight Roads | I7: Eight Roads (lead), Bessemer Venture Partners, Episode 1, Dynamo Ventures, Moguntia Capital | J7: AI automation platform | K7: Mid and large forwarders, customs brokers | L7: Air, Ocean, Road | M7: Document automation, email triage and invoice processing across the forwarding lifecycle | N7: Scale and enterprise credibility; documented deep CargoWise integration | O7: 95+ (UK, India, US) | P7: EMO Trans, OIA Global, The Scarbrough Group, NNR Global Logistics, Navia Freight | Q7: 60+ customers across 30+ countries; ~300,000 shipments/month; used by 40% of Armstrong & Associates' top-25 global forwarders | R7: raft.ai
A8: Reform (ReformHQ) | B8: United States | C8: United States | D8: US | E8: n/a | F8: n/a | G8: n/a | H8: Not disclosed | I8: Not disclosed | J8: AI automation platform | K8: Freight forwarders and logistics providers | L8: Multi-modal | M8: AI-first automation from quote to cash; connects documents and data across systems with human-in-the-loop exception handling | N8: Quote-to-cash breadth including AP/finance depth | O8: n/a | P8: Not disclosed publicly | Q8: Claims 20m+ tasks automated, 250,000 hours saved, US$500m+ AP invoices processed | R8: reformhq.com
A9: Levity | B9: Berlin | C9: Germany | D9: EU | E9: 2020 | F9: Seed / Series A | G9: 11.0 | H9: Not disclosed recently; pre-seed led by Angular Ventures | I9: Angular Ventures and others | J9: Email AI / no-code automation | K9: Forwarders and logistics SMBs | L9: Multi-modal | M9: Connects to the inbox, categorises incoming email, extracts the key fields and pushes them into the TMS | N9: No-code, email-first, low-friction entry point; pivoted from generic no-code AI into logistics | O9: ~25 | P9: Shine Logistics Group, Ultraship | Q9: Established logistics email-automation player; smallest deployment footprint of the EU cohort | R9: levity.ai
A10: Willidrop | B10: Munich | C10: Germany | D10: EU | E10: 2026 (launch) | F10: Pre-seed (undisclosed) | G10: n/a | H10: Undisclosed round announced on launch, 2026 | I10: Not disclosed | J10: Agentic AI workers (vertical) | K10: Vehicle / finished-car logistics operators | L10: Road (vehicle transport) | M10: Agent-based operating system for vehicle logistics, replacing email, phone and spreadsheet coordination of transport orders | N10: Deep vertical focus on finished-vehicle logistics rather than general forwarding | O10: n/a | P10: Not disclosed | Q10: Just emerged from stealth; same city and same thesis as 5U AI but a different vertical | R10: willidrop.com
A11: HappyRobot | B11: San Francisco | C11: United States | D11: US | E11: 2022 | F11: Series B | G11: 62.0 | H11: US$44m Series B, Sep 2025, led by Base10 Partners at ~US$500m valuation | I11: Base10 Partners (lead), Andreessen Horowitz, Y Combinator, Tokio Marine, WaVe-X, World Innovation Lab | J11: Agentic AI workers | K11: Brokers, 3PLs, carriers, and increasingly forwarders | L11: Road-heavy | M11: AI-native operating system for building custom AI workers that handle routine communication and operational tasks | N11: Best-funded pure-play in the category; voice depth; transparent per-action pricing model | O11: n/a | P11: Not disclosed publicly | Q11: ~US$62m raised since 2022; the reference point every US rival compares itself against | R11: happyrobot.ai
A12: Augment | B12: United States | C12: United States | D12: US | E12: 2024 | F12: Series A | G12: 85.0 | H12: US$85m Series A, Sep 2025, led by Redpoint | I12: Redpoint (lead), 8VC, Autotech Ventures | J12: Agentic AI workers | K12: Shippers, brokers and carriers | L12: Multi-modal | M12: 'Augie', an AI teammate performing seven logistics task types: quoting, dispatch, tracking, load building, billing, collections and comms | N12: Founder pedigree (Deliverr co-founder Harish Abbott) and the largest Series A in the category | O12: n/a | P12: Armstrong Transport Group | Q12: Supports US$35bn+ of freight under management; Armstrong reported ~40% reduction in invoice delays | R12: augment.co
A13: Vooma | B13: United States | C13: United States | D13: US | E13: 2023 (YC W23) | F13: Series A | G13: 16.6 | H13: US$13m Series A, Dec 2024, led by Craft Ventures (US$3.6m seed led by Index) | I13: Craft Ventures (lead), Index Ventures, Y Combinator | J13: Agentic AI workers | K13: Freight brokers and 3PLs | L13: Road | M13: AI agents for quoting, order entry, carrier communications, rate negotiation and appointment scheduling; Vooma Voice for telephony | N13: Aggressive competitive positioning - publishes head-to-head comparison pages against eight named rivals | O13: n/a | P13: Not disclosed publicly | Q13: Claims 93%+ automation of order entry | R13: vooma.com
A14: FleetWorks | B14: United States | C14: United States | D14: US | E14: n/a | F14: Seed / Series A | G14: 17.5 | H14: US$17m round led by First Round Capital | I14: First Round Capital (lead), Y Combinator, LFX Venture Partners, Saga Ventures | J14: Voice AI agents | K14: Freight brokerages, especially smaller ones | L14: Road | M14: AI carrier representatives and dispatchers that handle 100% of inbound calls and source carriers | N14: Voice-first; 24/7 phone coverage for brokers without night staff | O14: n/a | P14: Not disclosed publicly | Q14: n/a | R14: fleetworks.ai
... A30: cargo.one | B30: Berlin | C30: Germany | D30: EU | E30: 2017 | F30: Growth | G30: n/a | H30: US$20m (EUR 17m), Mar 2026, from Bessemer Venture Partners and other technology investors | I30: Bessemer Venture Partners and other technology investors | J30: Marketplace + AI-native OS | K30: Freight forwarders of all sizes; airlines and ocean carriers | L30: Air, Ocean | M30: AI-native operating system for multimodal freight - booking, rate management and sales automation in one platform | N30: Owns distribution: 28,000 forwarders already transact on the platform, so AI workflows reach them natively rather than being bolted onto separate systems | O30: n/a | P30: American Airlines Cargo; 28,000 forwarders on platform | Q30: Acquired Cargofive (ocean rates) in Mar 2026 and launched an AI-native multimodal OS | R30: cargo.one

Sheet Feature matrix
A1: Feature matrix
A2: Yes / Partial / No / Unknown. Coverage score = Yes counts 1, Partial counts 0.5, Unknown counts 0. Inferred from vendor marketing and press - directional, not a product audit.
A3: Company | B3: Email intake & agent | C3: Voice / telephony agent | D3: Chat & messaging (Teams/Slack/WhatsApp) | E3: Quoting & rate management | F3: Track & trace | G3: Document extraction | H3: Invoice reconciliation / AP | I3: Customs & compliance | J3: Booking & order entry | K3: Carrier portal automation | L3: TMS integration | M3: ERP / EDI / SFTP | N3: Human-in-the-loop approval | O3: Decision / audit log | P3: SOP-based configuration | Q3: Multilingual | R3: Pre-deployment training on history | S3: Self-serve sign-up | T3: Coverage score (of 18)
A4: 5U AI | B4: Yes | C4: Yes | D4: Yes | E4: Yes | F4: Yes | G4: Yes | H4: Yes | I4: No | J4: Yes | K4: Yes | L4: Yes | M4: Yes | N4: Yes | O4: Yes | P4: Yes | Q4: Yes | R4: Yes | S4: No | T4: =COUNTIF(B4:S4,"Yes")+0.5*COUNTIF(B4:S4,"Partial") -> 16
A5: Nexcade | B5: Yes | C5: Unknown | D5: Unknown | E5: Yes | F5: Unknown | G5: Yes | H5: Unknown | I5: No | J5: Yes | K5: Unknown | L5: Yes | M5: Unknown | N5: Yes | O5: Unknown | P5: Yes | Q5: Unknown | R5: Unknown | S5: No | T5: =COUNTIF(B5:S5,"Yes")+0.5*COUNTIF(B5:S5,"Partial") -> 7
A6: Cargofy | B6: Yes | C6: Yes | D6: Yes | E6: Partial | F6: Yes | G6: Yes | H6: Partial | I6: No | J6: Yes | K6: Partial | L6: Yes | M6: Yes | N6: Unknown | O6: Unknown | P6: Yes | Q6: Yes | R6: Unknown | S6: Unknown | T6: =COUNTIF(B6:S6,"Yes")+0.5*COUNTIF(B6:S6,"Partial") -> 11.5
A7: Raft (fka Vector.ai) | B7: Yes | C7: No | D7: Partial | E7: Partial | F7: Yes | G7: Yes | H7: Yes | I7: Yes | J7: Yes | K7: Partial | L7: Yes | M7: Yes | N7: Yes | O7: Partial | P7: Partial | Q7: Yes | R7: Unknown | S7: No | T7: =COUNTIF(B7:S7,"Yes")+0.5*COUNTIF(B7:S7,"Partial") -> 12.5
A8: Reform (ReformHQ) | B8: Yes | C8: Unknown | D8: Unknown | E8: Yes | F8: Partial | G8: Yes | H8: Yes | I8: Partial | J8: Yes | K8: Unknown | L8: Yes | M8: Unknown | N8: Yes | O8: Unknown | P8: Unknown | Q8: Unknown | R8: Unknown | S8: No | T8: =COUNTIF(B8:S8,"Yes")+0.5*COUNTIF(B8:S8,"Partial") -> 8
A9: Levity | B9: Yes | C9: No | D9: No | E9: Partial | F9: Partial | G9: Yes | H9: No | I9: No | J9: Partial | K9: No | L9: Yes | M9: Partial | N9: Partial | O9: No | P9: Partial | Q9: Unknown | R9: No | S9: Yes | T9: =COUNTIF(B9:S9,"Yes")+0.5*COUNTIF(B9:S9,"Partial") -> 7
A10: Willidrop | B10: Yes | C10: Unknown | D10: Unknown | E10: Partial | F10: Yes | G10: Unknown | H10: Unknown | I10: No | J10: Yes | K10: Unknown | L10: Unknown | M10: Unknown | N10: Unknown | O10: Unknown | P10: Unknown | Q10: Unknown | R10: Unknown | S10: Unknown | T10: =COUNTIF(B10:S10,"Yes")+0.5*COUNTIF(B10:S10,"Partial") -> 3.5
A11: HappyRobot | B11: Yes | C11: Yes | D11: Yes | E11: Partial | F11: Yes | G11: Partial | H11: Partial | I11: No | J11: Yes | K11: Partial | L11: Yes | M11: Yes | N11: Yes | O11: Yes | P11: Yes | Q11: Yes | R11: Unknown | S11: No | T11: =COUNTIF(B11:S11,"Yes")+0.5*COUNTIF(B11:S11,"Partial") -> 13
A12: Augment | B12: Yes | C12: Yes | D12: Yes | E12: Yes | F12: Yes | G12: Partial | H12: Yes | I12: No | J12: Yes | K12: Unknown | L12: Yes | M12: Unknown | N12: Yes | O12: Unknown | P12: Unknown | Q12: Unknown | R12: Unknown | S12: No | T12: =COUNTIF(B12:S12,"Yes")+0.5*COUNTIF(B12:S12,"Partial") -> 9.5
A13: Vooma | B13: Yes | C13: Yes | D13: Partial | E13: Yes | F13: Yes | G13: Partial | H13: No | I13: No | J13: Yes | K13: Partial | L13: Yes | M13: Unknown | N13: Yes | O13: Unknown | P13: Yes | Q13: Unknown | R13: Unknown | S13: No | T13: =COUNTIF(B13:S13,"Yes")+0.5*COUNTIF(B13:S13,"Partial") -> 9.5
A14: FleetWorks | B14: Partial | C14: Yes | D14: Partial | E14: Partial | F14: Yes | G14: No | H14: No | I14: No | J14: Yes | K14: No | L14: Yes | M14: Unknown | N14: Partial | O14: Unknown | P14: Unknown | Q14: Unknown | R14: Unknown | S14: No | T14: =COUNTIF(B14:S14,"Yes")+0.5*COUNTIF(B14:S14,"Partial") -> 6
A15: Drumkit | B15: Yes | C15: No | D15: No | E15: Partial | F15: Yes | G15: Yes | H15: No | I15: No | J15: Yes | K15: No | L15: Yes | M15: Unknown | N15: Partial | O15: Unknown | P15: Unknown | Q15: Unknown | R15: No | S15: Unknown | T15: =COUNTIF(B15:S15,"Yes")+0.5*COUNTIF(B15:S15,"Partial") -> 6
... A29: project44 / FourKites | B29: No | C29: No | D29: Partial | E29: No | F29: Yes | G29: No | H29: No | I29: No | J29: No | K29: No | L29: Yes | M29: Yes | N29: No | O29: Partial | P29: No | Q29: Yes | R29: No | S29: No | T29: =COUNTIF(B29:S29,"Yes")+0.5*COUNTIF(B29:S29,"Partial") -> 5
A31: Legend
A32: Yes
A33: Partial
A34: No
A35: Unknown
A36: Note: 'Unknown' means no public source was found, not an absent feature.

Sheet Pricing
A1: Pricing
A2: Only 2 of 26 vendors publish list prices. Everything else is sales-led. 'Confidence' separates confidence in the MODEL from confidence in the PRICE.
A3: Company | B3: Pricing published? | C3: Pricing model | D3: Billing unit | E3: Entry price | F3: Known price points | G3: Contract term | H3: Trial / pilot | I3: Confidence | J3: Basis
A4: 5U AI | B4: No - no pricing page exists | C4: Bespoke package per use case, agreed in an Order Form | D4: Not defined in the T&Cs; per-Worker strongly implied | E4: Not published | F4: None published. Inferred low tens of thousands of EUR ACV from the EUR 50,000 liability ceiling | G4: 2-year initial term, auto-renews up to 1 year, 3 months' notice, no termination for convenience | H4: Yes - trial phase per Order Form, 'As Is', no binding KPIs, either party may opt out | I4: Terms: High / Price: Low | J4: 5u.ai T&Cs cl. 3, 8, 14, 15; Founding Ops job spec ('pause, reduce, or stop a Worker')
A5: Nexcade | B5: No | C5: Enterprise, bespoke | D5: Unknown | E5: Not published | F5: None published | G5: Unknown | H5: Unknown | I5: Low | J5: No public pricing found
A6: Cargofy | B6: No | C6: Subscription | D6: Unknown | E6: Not published | F6: Derived: ~US$5,000 average ARR per customer (US$10m ARR / 2,000 customers) - see Pricing benchmarks tab | G6: Unknown | H6: Unknown | I6: Derived: Medium | J6: EU-Startups and Vestbee coverage of the Jun 2026 Series A
A7: Raft (fka Vector.ai) | B7: No | C7: Subscription with custom enterprise pricing | D7: Likely platform fee plus volume | E7: Not published | F7: None published | G7: Unknown | H7: Unknown | I7: Low | J7: SaaSworthy lists 'custom plan' only
A8: Reform (ReformHQ) | B8: No | C8: Enterprise | D8: Unknown | E8: Not published | F8: None published | G8: Unknown | H8: Unknown | I8: Low | J8: No public pricing found
A9: Levity | B9: YES - published | C9: Hybrid: flat base plus per-unit usage | D9: Per month plus per processed email | E9: US$79/month | F9: US$79/month base, plus US$0.05-0.30 per processed email depending on volume and complexity | G9: Unknown | H9: Self-serve | I9: High | J9: CORRECTION 30 Jul 2026: pricing located via GetApp. Previously recorded as unpublished.
A10: HappyRobot | B10: No - but the model is public | C10: Per-action (outcome-style) | D10: Per action: scheduling a load, updating a status, processing a rate confirmation | E10: Not published | F10: Fixed price per action; you pay only for actions the agent performs. Market benchmarks: US$0.30-1.00 per ticket, US$0.50-2.00 per resolution | G10: Unknown | H10: Unknown | I10: Model: High / Price: Low | J10: HappyRobot pricing hub; 2026 AI-agent pricing surveys
A11: Augment | B11: No | C11: Enterprise | D11: Unknown | E11: Not published | F11: None published | G11: Unknown | H11: Unknown | I11: Low | J11: No public pricing found
A12: Vooma | B12: No | C12: Subscription plus usage | D12: Unknown | E12: Not published | F12: None published | G12: Unknown | H12: Unknown | I12: Low | J12: No public pricing found
A13: FleetWorks | B13: No | C13: Likely per-call / usage | D13: Unknown | E13: Not published | F13: None published | G13: Unknown | H13: Unknown | I13: Low | J13: No public pricing found
A14: Drumkit | B14: No | C14: Subscription | D14: Likely per seat | E14: Not published | F14: None published | G14: Unknown | H14: Unknown | I14: Low | J14: No public pricing found
... A24: project44 / FourKites | B24: No | C24: Enterprise, volume-based | D24: Per shipment / per lane | E24: Not published | F24: None published | G24: Multi-year enterprise | H24: No | I24: Low | J24: No public pricing found

Sheet Vs 5U AI
A1: Head-to-head vs 5U AI
A2: Threat level is a judgement call based on product overlap, buyer overlap, geography and capital.
A3: Company | B3: Region | C3: Overlap with 5U AI | D3: Threat level | E3: Where they beat 5U AI | F3: Where 5U AI beats them | G3: What to watch
A4: Nexcade | B4: UK | C4: Very high - same product, same buyer, same continent | D4: CRITICAL | E4: US$8.5m vs US$3.2m raised; enterprise logos (XPO, Zencargo) at seed stage; founder was COO of Sedna, so deep forwarding relationships and distribution | F4: 5U AI's Decision Layer is a sharper articulated moat; Nexcade explicitly keeps humans in the final decision, so its automation ceiling may be lower; 5U AI has DACH-native, German-speaking delivery | G4: Whether Nexcade moves into DACH. Same product thesis announced three weeks before 5U AI's round.
A5: Cargofy | B5: EU | C5: High on product, medium on buyer (road/dispatch-heavy) | D5: HIGH | E5: US$10m+ ARR and 2,000 paying customers - roughly an order of magnitude ahead commercially; 70+ integrations; already in EU and US | F5: 5U AI targets forwarders rather than carriers/dispatch; deeper air and ocean workflow specificity; DACH enterprise positioning | G5: If Cargofy moves up-market from carriers into forwarding, its price point and integration breadth become very hard to beat.
A6: Raft (fka Vector.ai) | B6: UK | C6: High - overlapping workflows, larger customers | D6: HIGH | E6: US$47.7m raised, 60+ customers, 300,000 shipments/month, proven CargoWise integration, customs coverage; the safe enterprise choice | F6: Raft is document- and triage-centric rather than a true agentic worker; analysts note quoting is not its core engine; 5U AI is more agent-native and faster to configure | G6: Raft adding agentic workers on top of its installed base would be the single biggest competitive event.
A7: Reform (ReformHQ) | B7: US | C7: High on workflow scope (quote to cash) | D7: MEDIUM | E7: Large claimed automation volumes and AP depth; quote-to-cash breadth | F7: 5U AI is EU-native with GDPR posture and European hosting; Reform has no visible EU presence | G7: US entrants crossing the Atlantic; watch for an EU office or a European logo.
A8: Levity | B8: EU | C8: Medium - same channel (email), shallower product | D8: MEDIUM | E8: Established in logistics email automation since before the agentic wave; low-friction, self-serve entry; Berlin-based, so same market | F8: Levity classifies and extracts; 5U AI executes end to end with approval, portal automation and voice. Very different automation ceiling | G8: Levity repositioning from 'email AI' to 'AI workers' would compress 5U AI's differentiation in DACH.
A9: Willidrop | B9: EU | C9: Low - adjacent vertical, same city and thesis | D9: LOW | E9: Vertical depth in finished-vehicle logistics; Munich talent competition | F9: Different buyer entirely; no overlap in air/ocean forwarding | G9: Talent and investor attention in Munich rather than customer overlap.
A10: HappyRobot | B10: US | C10: High on product, low on buyer today | D10: HIGH (strategic) | E10: US$62m raised at ~US$500m valuation; voice depth; per-action pricing that buyers find easy to justify; sets the category's pricing norms | F10: Road/brokerage-centric; 5U AI owns air and ocean forwarding workflows and EU data residency | G10: Any HappyRobot move into European forwarding. Their per-action pricing may also force 5U AI off bespoke annual contracts.
A11: Augment | B11: US | C11: Medium-high on product, low on geography | D11: MEDIUM | E11: US$85m Series A, elite founder pedigree, US$35bn freight under management | F11: US-centric shipper/broker focus; 5U AI is EU forwarder-native | G11: Redpoint-backed companies expand fast. Watch for a European launch.
A12: Vooma | B12: US | C12: Medium - same workflows, US brokerage buyer | D12: MEDIUM | E12: US$16.6m raised; strong quoting and voice; publishes aggressive competitive comparisons | F12: No EU presence; brokerage rather than forwarding | G12: Their comparison-page playbook is worth copying for 5U AI's own GTM.
A13: FleetWorks / Lanesurf / CloneOps | B13: US | C13: Low-medium - voice-only slice | D13: LOW | E13: Voice AI maturity well ahead of 5U AI's claimed voice channel | F13: 5U AI covers the full workflow, not just the call | G13: If 5U AI markets voice, these set the quality bar buyers will compare against.
A14: Drumkit | B14: US | C14: Medium - email-native, similar shape, much smaller | D14: LOW | E14: YC network and brand; simple adoption | F14: US$2.56m raised and email-only scope; 5U AI is broader and better funded | G14: Least threatening of the US cohort.
... A24: Horizontal platforms (Copilot Studio, n8n, UiPath, DIY) | B24: All | C24: Competes in the sales cycle, not on outcome - the default IT-led objection in every deal | D24: HIGH (sales-cycle) | E24: Perceived as near-free (Copilot US$200/month credit packs; n8n self-hosted at EUR 0); already owned by the customer's IT; no procurement needed | F24: No freight context, no shipment state, no portal resilience, no HITL queue, no audit layer; in-house AI failure base rates of 80-95% (RAND, MIT) | G24: See the Horizontal platforms tab for the full analysis and per-platform objection handling.

Sheet Pricing benchmarks
A1: Pricing benchmarks and derived metrics
A2: Blue cells are inputs from named sources. Black cells are formulas.
A4: Benchmark | B4: Low | C4: High | D4: Source / note
A5: AI agent, per seat (per user per month, US$) | B5: 30 | C5: 80 | D5: 2026 AI-agent pricing surveys
A6: AI agent, per ticket / inbound conversation (US$) | B6: 0.3 | C6: 1 | D6: 2026 AI-agent pricing surveys
A7: AI agent, per resolution, outcome-based (US$) | B7: 0.5 | C7: 2 | D7: Not billed on escalation; beats per-seat above ~3,000 conversations/month
A8: Entry-level TMS (per user per month, US$) | B8: 50 | C8: 150 | D8: GoFreight market commentary, 2026
A9: Mid-market TMS (per user per month, US$) | B9: 100 | C9: 400 | D9: GoFreight market commentary, 2026
A10: Enterprise TMS (per user per month, US$) | B10: 500 | C10: 2000 | D10: GoFreight market commentary, 2026
A11: Quotiss rate management (per user per month, US$) | B11: 69 | C11: 129 | D11: quotiss.com published pricing; Pro tier requires 50+ active accounts
A12: Freightos Terminal rate data (per month, US$) | B12: 119 | C12: 239 | D12: Ocean US$119, Air US$239, billed annually
A15: DERIVED: Cargofy average revenue per customer
A16: Reported ARR (US$) | B16: 10000000 | D16: 'surpassed $10 million in annual recurring revenue' - EU-Startups, Jun 2026
A17: Reported paying customers | B17: 2000 | D17: '2,000 paying customers across Europe, the US and the Caspian region'
A18: Average ARR per customer (US$) | B18: =IF(B17=0,"n/a",B16/B17) -> 5000 | D18: Blended across a mixed base of carriers, brokers and dispatchers, so it is a floor for enterprise deals rather than a list price. Still the only hard revenue-per-customer figure available for any AI-worker vendor in this set.
A21: DERIVED: 5U AI implied contract-value ceiling
A22: Absolute liability cap in T&Cs (EUR) | B22: 50000 | D22: 5u.ai Terms & Conditions, clause 14.2: greater of EUR 10,000 or 100% of prior-12-month fees, never exceeding EUR 50,000.
A23: Inference | B23: EUR 10k-50k ACV | D23: A vendor does not cap total liability at EUR 50,000 if typical contracts are six figures - buyers' legal teams reject it. Reasoned inference, NOT a disclosed figure.

Sheet Pricing recommendation
A1: 5U AI - Pricing recommendation
A2: Derived from the competitor set in this workbook and from 5U AI's own Terms & Conditions. Yellow cells are assumptions you can change - every figure below recalculates.
A4: 1. THE RECOMMENDATION
A5: Recommendation | F5: Why
A6: Price the AI Worker, never the seat | F6: The entire pitch is '10x output at the cost of one employee'. Per-seat pricing means revenue falls as the product succeeds and headcount drops - the buyer notices this before you do. Per-Worker also matches the land-and-expand motion already written into the Founding Ops spec (expand by workflow, team and location).
A7: Use a hybrid: platform fee + per-Worker subscription + usage above an included band | F7: Hybrid base-plus-usage is now 41% of the AI market and per-seat has fallen to 15%. A pure per-action model (HappyRobot) suits high-volume broker calls, not a mid-market forwarder CFO who needs a predictable number.
A8: Anchor on the labour cost released, not on software comparables | F8: Anchoring on software loses: Quotiss is US$69/user/month and CargoWise bundles a rate module into an existing licence. Anchoring on a German ops FTE at ~EUR 62k makes a EUR 30k contract look cheap rather than expensive.
A9: Ramp the Worker fee against automation rate | F9: Charge 50% of the Worker fee until automation rate reaches 60%, then full fee. Automation rate is already the customer-health metric in the Ops job spec, so this aligns price with the number both sides watch - and it removes the biggest objection to a long commitment from an unproven vendor.
A10: Sell a paid pilot, not a free trial | F10: A priced 3-month pilot credited against year one qualifies the buyer, funds the forward-deployed engineer, and replaces the current 'As Is, no binding KPIs' trial clause that gives away the only leverage you have.
A12: 2. VALUE ANCHOR - what one AI Worker actually releases
A13: Assumption | B13: Value | F13: Source / rationale
A14: Fully loaded annual cost of one ops FTE (EUR) | B14: 62000 | F14: German/DACH mid-market logistics ops salary plus employer costs. Change this per market.
A15: Ops FTE-equivalents one Core Worker touches | B15: 2 | F15: A Rate Manager or Track & Trace Worker typically spans the workload of two operators.
A16: Share of their day the Worker absorbs | B16: 0.7 | F16: 5U AI's own published claim: 70% of a daily operations person's day saved.
A17: Automation rate achieved at steady state | B17: 0.9 | F17: 5U AI states 85-95% unattended automation per use case. 90% is the midpoint.
A18: Annual value released per Core Worker (EUR) | B18: =B14*B15*B16*B17 -> 78120 | F18: This is the number the whole rate card is priced against.
A19: Blue figures on a yellow fill are inputs. Everything else is a formula.
A21: 3. RECOMMENDED RATE CARD (EUR, list price, ex-VAT)
A22: Component | B22: Unit | C22: List price | F22: Rationale
A23: Platform fee | B23: per customer / year | C23: 12000 | F23: Covers hosting, tenant isolation, the audit log, dashboards and support. Makes the first Worker cheaper and every additional Worker high-margin.
A24: Core AI Worker (Rate Manager, Track & Trace) | B24: per Worker / year | C24: 18000 | F24: The two use cases 5U AI's own FAQ names as highest ROI. Priced at roughly 23% of the value released.
A25: Extended AI Worker (Invoice recon, After-hours, DocuMind) | B25: per Worker / year | C25: 12000 | F25: Lower value density and lower delivery effort; prices the expansion motion attractively.
A26: Included transactions per Core Worker | B26: per Worker / year | C26: 9000 | F26: ~750/month. A quote, a shipment tracked, or an invoice reconciled each count as one transaction.
A27: Overage above included band | B27: per transaction | C27: 1.2 | F27: Sits inside the US$0.50-2.00 outcome-based benchmark on the Pricing benchmarks tab.
A28: Onboarding and deployment (first Worker) | B28: one-off | C28: 9500 | F28: Funds the Forward Deployed Engineer through the ~4-week go-live. Do not give this away.
A29: Additional site or legal entity onboarding | B29: one-off | C29: 4500 | F29: Multi-site forwarders are the main expansion path.
A30: Paid pilot - 1 Worker, 3 months | B30: fixed | C30: 9500 | F30: Fully credited against year one on conversion. Replaces the current unpriced trial.
A31: Implied price per transaction at included volume (EUR) | B31: =C24/C26 -> 2 | F31: Check figure. A sophisticated buyer will compute this. At the top of the outcome-based benchmark band, which is defensible because a freight quote carries far more margin than a support ticket.
A33: 4. PACKAGES AND ROI (all figures calculated from sections 2 and 3)
A34: Metric | B34: Pilot | C34: Launch | D34: Scale | E34: Enterprise | F34: Notes
A35: Term (months) | B35: 3 | C35: 12 | D35: 12 | E35: 12 | F35: Recommend a 12-month initial term for Launch and Scale.
A36: Core Workers | B36: 1 | C36: 1 | D36: 2 | E36: 4
A37: Extended Workers | B37: 0 | C37: 0 | D37: 1 | E37: 2
A38: Ops FTE-equivalents covered | B38: 2 | C38: 2 | D38: 5 | E38: 10 | F38: Core Workers cover ~2 operators each; Extended Workers ~1.
A39: Contract value over term (EUR) | B39: =$C$30 -> 9500 | C39: =($C$23+C36*$C$24+C37*$C$25)*C35/12 -> 30000 | D39: =($C$23+D36*$C$24+D37*$C$25)*D35/12 -> 60000 | E39: =($C$23+E36*$C$24+E37*$C$25)*E35/12 -> 108000 | F39: Excludes one-off onboarding of EUR 9,500, which is invoiced separately.
A40: Value released over term (EUR) | B40: =$B$14*B38*$B$16*$B$17*B35/12 -> 19530 | C40: =$B$14*C38*$B$16*$B$17*C35/12 -> 78120 | D40: =$B$14*D38*$B$16*$B$17*D35/12 -> 195300 | E40: =$B$14*E38*$B$16*$B$17*E35/12 -> 390600 | F40: Labour capacity released, using the section 2 assumptions.
A41: ROI multiple | B41: =IFERROR(B40/B39,"n/a") -> 2.0557895 | C41: =IFERROR(C40/C39,"n/a") -> 2.604 | D41: =IFERROR(D40/D39,"n/a") -> 3.255 | E41: =IFERROR(E40/E39,"n/a") -> 3.6166667 | F41: Target 2.5-4x. Anything above 5x means you are underpricing; the 15x in current marketing is not credible and invites scrutiny.
A42: Payback (months) | B42: =IFERROR(B39/(B40/B35),"n/a") -> 1.4592934 | C42: =IFERROR(C39/(C40/C35),"n/a") -> 4.6082949 | D42: =IFERROR(D39/(D40/D35),"n/a") -> 3.6866359 | E42: =IFERROR(E39/(E40/E35),"n/a") -> 3.3179724 | F42: Under 6 months is the threshold that gets a mid-market forwarder to sign without a committee.
A43: Annualised contract value (EUR) | B43: =B39*12/B35 -> 38000 | C43: =C39*12/C35 -> 30000 | D43: =D39*12/D35 -> 60000 | E43: =E39*12/E35 -> 108000 | F43: Comparison figure only. The Pilot annualises artificially high because it is a fixed fee.
A45: 5. COMMERCIAL TERMS TO CHANGE
...

Sheet Market sizing
A1: Agentic AI in freight forwarding - market sizing
A2: EU, UK and US. Two independent methods, deliberately triangulated against each other. Yellow cells are assumptions; pale blue cells are sourced facts. Everything else is a formula.
A4: 1. METHOD
A5: Approach A - labour value | F5: Sizes the pool of operational labour cost that agents can absorb, then applies a vendor value-capture rate. Answers: how large could this category become?
A6: Approach B - bottom-up firm count | F6: Counts the addressable companies and multiplies by a realistic contract value. Answers: how much revenue is reachable with today's product, ICP and price points?
A7: Why both | F7: They disagree by roughly 20x, and the gap is the most important finding on this tab. See section 6.
A9: 2. BASE DATA (sourced)
A10: Metric | B10: Value | F10: Source
A11: EU forwarding, logistics and customs companies | B11: 19000 | F11: CLECAT, the European forwarding association - members it represents
A12: EU forwarding, logistics and customs staff | B12: 1000000 | F12: CLECAT
A13: Germany - leading forwarding and logistics companies | B13: 2500 | F13: DSLV Bundesverband Spedition und Logistik
A14: Germany - forwarding and logistics employees | B14: 600000 | F14: DSLV, October 2025
A15: Germany - annual sector revenue (EUR) | B15: 123000000000 | F15: DSLV, October 2025
A16: UK - BIFA corporate members | B16: 1700 | F16: British International Freight Association
A17: US - freight forwarding employer businesses | B17: 15418 | F17: US Census, NAICS 488510, 2020
A18: US - freight forwarding brokerages and agencies (incl. agents) | B18: 75407 | F18: IBISWorld - counts sole traders and agents, hence the gap vs Census
A19: US - freight forwarding employees | B19: 347783 | F19: IBISWorld, 2024
A20: US - market size 2026 (USD) | B20: 127700000000 | F20: IBISWorld, Freight Forwarding Brokerages & Agencies
A21: Europe - freight forwarding market by 2030 (USD) | B21: 86620000000 | F21: Grand View Research, 5.9% CAGR from 2025
A22: Company counts are association membership or statistical registers, not complete universes. CLECAT's 19,000 covers established forwarders; the true long tail of micro-forwarders is larger.
A24: 3. APPROACH A - LABOUR-VALUE TAM
A25: Driver | B25: EU | C25: UK | D25: US | E25: Total | F25: Basis
A26: Forwarding sector staff | B26: =B12 -> 1000000 | C26: 85000 | D26: =B19 -> 347783 | E26: =SUM(B26:D26) -> 1432783 | F26: EU and US sourced. UK is an ESTIMATE - replace with BIFA or IBISWorld UK data when available.
A27: Share in operational / back-office roles | B27: 0.5 | C27: 0.5 | D27: 0.5 | F27: Quoting, order entry, track & trace, documents, invoicing. ASSUMPTION - the least evidenced input here.
A28: Fully loaded cost per ops FTE (EUR) | B28: 62000 | C28: 58000 | D28: 78000 | F28: DACH mid-market benchmark for the EU; US uplifted for salary levels.
A29: Total ops labour cost (EUR) | B29: =B26*B27*B28 -> 31000000000 | C29: =C26*C27*C28 -> 2465000000 | D29: =D26*D27*D28 -> 13563537000 | E29: =SUM(B29:D29) -> 47028537000 | F29: Calculated
A30: Share of that work addressable by agents | B30: 0.6 | C30: 0.6 | D30: 0.6 | F30: 5U AI claims 70% of an ops day is repetitive; discounted for the share never fully automatable. ASSUMPTION.
A31: Vendor value-capture rate | B31: 0.12 | C31: 0.12 | D31: 0.12 | F31: Share of displaced labour cost a software vendor converts to revenue. Early-category vendors capture far less; mature ones more. ASSUMPTION and the single biggest swing factor.
A32: TAM - annual revenue opportunity (EUR) | B32: =B29*B30*B31 -> 2232000000 | C32: =C29*C30*C31 -> 177480000 | D32: =D29*D30*D31 -> 976574664 | E32: =SUM(B32:D32) -> 3386054664 | F32: The ceiling on the category, not on any one vendor.
A34: 4. APPROACH B - BOTTOM-UP FIRM COUNT
A35: Driver | B35: EU | C35: UK | D35: US | E35: Total | F35: Basis
A36: Companies in the register / association base | B36: =B11 -> 19000 | C36: =B16 -> 1700 | D36: =B17 -> 15418 | E36: =SUM(B36:D36) -> 36118 | F36: US uses the Census employer-business count, not IBISWorld's agent-inclusive figure.
A37: Share with 100-500 employees (the stated ICP) | B37: 0.04 | C37: 0.06 | D37: 0.04 | F37: Derived from the standard EU size distribution: ~99% of enterprises are SMEs and ~1% exceed 250 staff. ASSUMPTION - the band is narrow and the estimate is coarse.
A38: Companies in the core ICP | B38: =B36*B37 -> 760 | C38: =C36*C37 -> 102 | D38: =D36*D37 -> 616.72 | E38: =SUM(B38:D38) -> 1478.72 | F38: Calculated
A39: Mature annual contract value (EUR) | B39: 75000 | C39: 75000 | D39: 85000 | F39: Platform fee plus roughly four Workers, per the rate card on the Pricing recommendation tab.
A40: SAM - core ICP fully penetrated (EUR) | B40: =B38*B39 -> 57000000 | C40: =C38*C39 -> 7650000 | D40: =D38*D39 -> 52421200 | E40: =SUM(B40:D40) -> 117071200 | F40: Every single ICP company buying, at mature ACV. A ceiling, not a forecast.
A42: Extended SAM - widen the ICP to 50+ employees
A43: Share with 50+ employees | B43: 0.095 | C43: 0.08 | D43: 0.052 | F43: Adds the 50-99 band, which a lighter-touch product could reach. ASSUMPTION.
A44: Companies, 50+ employees | B44: =B36*B43 -> 1805 | C44: =C36*C43 -> 136 | D44: =D36*D43 -> 801.736 | E44: =SUM(B44:D44) -> 2742.736 | F44: Calculated
A45: Blended ACV across the wider band (EUR) | B45: 55000 | C45: 55000 | D45: 62000 | F45: Lower, because smaller firms buy fewer Workers.
...

Sheet GTM and ICP
A1: Competitor GTM strategies and ICP profiles
A2: Compiled 30 July 2026 from vendor sites, funding coverage, job specifications and partner announcements. 5U AI is the highlighted baseline row.
A4: Company | B4: Region | C4: ICP - company type | D4: ICP - size band | E4: ICP - geography | F4: Buyer persona | G4: Primary GTM motion | H4: Secondary channels | I4: Land-and-expand pattern | J4: Entry point | K4: Named customers | L4: Notable - and what 5U AI can take from it
A5: 5U AI | B5: EU | C5: Mid-sized freight forwarders | D5: 100-500 employees | E5: DACH + Benelux | F5: Head of Operations / Managing Director | G5: Founder-led outbound and inbound. Zero marketing spend to date; no SDR or marketing engine yet | H5: Industry events and forwarder networks, per the Founding GTM job spec | I5: Expand by workflow, team and location; the Ops hire owns upsell | J5: Sales-led plus forward-deployed; ~4 weeks workshop to live | K5: TCI International Logistics | L5: This is the baseline. The motion is entirely founder-dependent, which the Founding GTM hire is meant to fix.
A6: Nexcade | B6: UK | C6: Freight forwarders including large enterprises | D6: Enterprise and upper mid-market | E6: Europe and US | F6: Pricing and operations leadership | G6: Design partnerships converted into production deployments; enterprise-logo led | H6: Founder network from Sedna; Project A and Connect Ventures introductions | I6: Job-specific agents; expand workflow by workflow | J6: Sales-led, design-partner first | K6: XPO, Zencargo, Cardinal Global Logistics, CargoTrans | L6: Won named enterprise logos before its seed round by starting as design partnerships rather than paid pilots. 5U AI has one named customer against their four.
A7: Cargofy | B7: EU | C7: Carriers, brokers, 3PLs and dispatch teams | D7: SMB to mid-market fleet operators | E7: Europe, US and Caspian | F7: Dispatch manager / fleet owner | G7: High-volume, low-ACV land. 2,000 paying customers at roughly US$5,000 each | H7: 70+ tool integrations function as distribution; multi-language coverage | I7: Deployed as a utility layer inside the customer's own business | J7: Low-touch, closer to self-serve than enterprise | K7: Not named publicly; a 315-truck fleet deployment is cited | L7: Proof that volume can beat ACV. US$10m ARR built on thousands of small contracts, not dozens of large ones.
A8: Raft | B8: UK | C8: Forwarders and customs brokers | D8: Mid to large; 60+ customers in 30+ countries | E8: Global, including 40% of the Armstrong top-25 | F8: COO, Head of Operations, Finance lead | G8: Enterprise sales with a genuine partner channel | H8: CargoWise integration and a PayCargo payments partnership as distribution | I8: Land on documents and email triage, expand into financial operations | J8: Sales-led enterprise | K8: EMO Trans, OIA Global, Scarbrough Group, NNR Global Logistics, Navia Freight | L8: The clearest partnership-as-distribution play in the set. Being the documented CargoWise integration wins deals before a salesperson is involved.
A9: cargo.one | B9: EU | C9: Forwarders of all sizes, plus airlines and ocean carriers | D9: 28,000 forwarders, SMB to global | E9: Global | F9: Procurement and pricing teams; carrier commercial teams | G9: Two-sided marketplace. Carriers pay for distribution; forwarders get the tooling | H9: Airline partnerships (American Airlines Cargo); a dedicated SMB product line | I9: Owns the booking rail, then layers AI on top; acquired Cargofive for ocean rate data | J9: Self-serve for forwarders | K9: American Airlines Cargo; 28,000 forwarders on platform | L9: The distribution threat nobody in this category can match. If cargo.one ships agentic workflows, it reaches 28,000 forwarders on day one.
A10: Reform | B10: US | C10: Freight forwarders and logistics providers | D10: Mid-market | E10: North America, LATAM, Europe | F10: Operations leadership | G10: Y Combinator network plus content-led credibility | H10: Podcast appearances and published case studies | I10: Quote-to-cash breadth across the whole operational span | J10: Sales-led | K10: Not named; a mid-size forwarder case study claims ~1,500 hours saved per month | L10: Content and case studies doing the work a sales team would otherwise do. Cheap, and 5U AI publishes almost nothing.
A11: Levity | B11: EU | C11: Freight brokerages, air cargo carriers, 3PLs | D11: SMB and lower mid-market | E11: Europe and US | F11: Operations manager | G11: Product-led growth - the only true PLG motion in EU forwarding AI | H11: Published pricing and a low entry point remove the sales conversation | I11: Land on email classification, expand with volume | J11: Self-serve from US$79/month plus per-email usage | K11: Shine Logistics Group, Ultraship | L11: Proves a forwarder will swipe a card for this category. Their base-plus-usage model is exactly what section 12 recommends for 5U AI.
A12: HappyRobot | B12: US | C12: Brokers and 3PLs, now retailers, manufacturers, 4PLs and carriers | D12: Mid-market to enterprise | E12: US primarily | F12: COO / operations leadership | G12: Forward-deployed engineers working on-site with customers | H12: project44 partnership; Microsoft for Startups programme | I12: Expand across workflows once the first deployment proves out | J12: Sales-led plus FDE | K12: Not named publicly | L12: The same forward-deployed model as 5U AI, executed with roughly twenty times the capital. Watch how they industrialise it.
A13: Augment | B13: US | C13: Shippers, brokers, carriers and distributors | D13: Enterprise; US$35bn freight under management | E13: US | F13: C-suite | G13: Enterprise land with large logos, funded by aggressive hiring | H13: Founder brand from Deliverr; 50+ engineers and 10+ GTM hires planned | I13: Front-office quoting and dispatch, then back-office billing and compliance | J13: Sales-led enterprise | K13: Armstrong Transport Group | L13: Their ACV growth path is scope expansion from front office to back office - the same move available to 5U AI.
A14: Vooma | B14: US | C14: Freight brokers and carriers | D14: Top-tier brokers | E14: US | F14: Broker operations leadership | G14: Named-logo enterprise sales plus competitive-comparison SEO | H14: Published comparison pages against eight named rivals; Highway partnership for carrier identity | I14: A product ladder: Quote, then Build, then Voice | J14: Sales-led | K14: Echo, MODE, Arrive Logistics, NFI | L14: The comparison-page playbook is directly copyable and costs almost nothing. 5U AI currently ranks for nothing.
A15: FleetWorks | B15: US | C15: Freight brokerages, especially smaller ones | D15: SMB brokers | E15: US | F15: Broker owner / operations | G15: Voice-first wedge: take over 100% of inbound calls | H15: Y Combinator and First Round networks | I15: Land on inbound calls, expand into dispatch | J15: Sales-led | K15: Not named publicly | L15: A narrow wedge with obvious, immediate value. Contrast with 5U AI's broader but slower four-week deployment.
... A20: CargoWise (WiseTech) | B20: Other | C20: Forwarders globally | D20: All sizes | E20: Global | F20: CIO / IT leadership | G20: Licence bundling through an established partner ecosystem | H20: Certified partner network with training and certification | I20: Bundles new modules into an existing licence at near-zero marginal price | J20: Enterprise licence | K20: Most large global forwarders | L20: The platform-bundling risk. Every integration 5U AI builds deepens both the moat and the dependency.
A22: GTM ARCHETYPES OBSERVED
A23: 1. Forward-deployed enterprise | C23: 5U AI, HappyRobot, Nexcade, Raft. An engineer embeds, builds the deployment, and the account expands from there. Highest ACV and highest trust, but capacity-bound: growth is limited by how many engineers you can hire, not how much demand you can generate.
A24: 2. Product-led self-serve | C24: Levity, cargo.one's SMB line, Drumkit. Published price, card payment, no sales conversation. Reaches the long tail that forward-deployed delivery can never serve economically. Levity is the only EU forwarding AI vendor running this properly.
A25: 3. Two-sided marketplace | C25: cargo.one, Freightos. The carrier side funds distribution to the forwarder side. Structurally the strongest position in the category, and the hardest to build from a standing start.
A26: 4. Partnership-as-distribution | C26: Raft with CargoWise and PayCargo; Wisor with Lufthansa Cargo and Emirates SkyCargo; HappyRobot with project44; Vooma with Highway. Being the documented integration wins deals before a salesperson is involved. Notably absent from 5U AI's motion.
A27: 5. Competitive-comparison demand capture | C27: Vooma publishes head-to-head pages against eight named rivals and captures prospects already in evaluation. Near-zero cost, and it works because buyers in this category search by vendor name.
A29: ICP PATTERNS - WHAT THE FIELD HAS CONVERGED ON
A30: The US cohort sells to brokers | C30: HappyRobot, Vooma, FleetWorks, Lanesurf, Drumkit and Parade all target freight brokerages and road transport. That market is larger, more consolidated and faster-moving than European forwarding - which is precisely why it is crowded and why the European forwarding lane remains relatively open.
A31: The EU/UK cohort sells to forwarders | C31: 5U AI, Nexcade, Raft and cargo.one all target freight forwarders in air and ocean. This is the contested lane, and it now has four funded participants, one of which owns the booking rail.
A32: Everybody is drifting toward the same ICP | C32: HappyRobot started with brokers and expanded into 3PLs, 4PLs, retailers and manufacturers across ocean, air and truckload. Nexcade has moved into the US. Cargofy already covers Europe, the US and the Caspian. The geographic and segment moats are thinner than any single vendor's positioning suggests.
A33: Size band is the real differentiator | C33: Cargofy proves the sub-100-employee segment is monetisable at roughly US$5,000 per account. cargo.one proves the SMB long tail can be reached self-serve. 5U AI's 100-500 employee band is the narrowest ICP of any funded player in the set - a few hundred companies in the beachhead, per the Market sizing tab.
A35: IMPLICATIONS FOR 5U AI
A36: Missing: a partner channel | C36: Every scaled competitor has one. Raft's CargoWise integration, Wisor's carrier connections, HappyRobot's project44 tie-up. 5U AI already integrates WiseTech and Timocom but does not market either as a channel.
A37: Missing: any published content | C37: Two blog posts total. Reform builds credibility through podcasts and case studies; Vooma captures demand through comparison pages. Both are cheap and neither requires the commercial hire to be in place first.
A38: Missing: a named reference customer at scale | C38: Nexcade lists XPO and Zencargo at seed stage. 5U AI lists one customer. In a market where forwarders buy on peer proof, this is the single most valuable thing the first commercial hire could produce.
A39: Risk: the ICP is the narrowest in the field | C39: A few hundred addressable companies in the beachhead. Either widen the band, or accept that expansion within accounts - not new logos - has to carry the growth.
A40: Risk: cargo.one owns the distribution | C40: 28,000 forwarders already on platform, now with an AI-native OS and an ocean rate platform acquired. They do not need to win a sales cycle to reach 5U AI's prospects.

Sheet Whitespace
A1: Whitespace analysis - where demand exists and no funded competitor is positioned
A2: Derived by crossing the Feature matrix (workflow coverage), the GTM and ICP tab (motions run) and the Market sizing tab (segments reachable). Ordered by actionability for 5U AI. Mirrors dossier section 15.
A4: # | B4: Whitespace | C4: Why it is open | D4: Evidence | E4: For 5U AI | F4: Which lever it pulls
A5: 1 | B5: Self-serve agentic product for sub-100-employee forwarders | C5: Every agentic vendor in EU forwarding is sales-led and forward-deployed; the long tail cannot be served economically that way. Levity is self-serve but stops at email classification - it does not execute. | D5: Feature matrix: 'self-serve sign-up' is No or Unknown for every agentic vendor. Market sizing: the sub-100 tail is the majority of ~19,000 EU forwarders and is excluded from every funded player's ICP. | E5: The single largest structural opportunity, and the one the market-sizing arithmetic demands. A cut-down, one-Worker, fixed-price product (~EUR 500-1,000/month) would be the first true PLG agentic offer in EU forwarding. | F5: More addressable companies
A6: 2 | B6: Customs and compliance workflow | C6: The one major forwarding workflow no agentic worker covers. Only Digicust (EUR 2.3m seed) addresses it, as a point solution - and the EU Customs Reform digitises core processes from 2026, forcing every forwarder to change how declarations are filed. | D6: Feature matrix: customs is No for 5U AI, Nexcade, Cargofy, HappyRobot, Augment and Vooma alike. A regulatory forcing function with a structural deadline is rare. | E6: Partner with or acquire Digicust-class capability, or build a Customs Worker. Whoever adds customs to an agentic suite first claims 'end-to-end' credibly - and closes the gap a rival could otherwise use against 5U AI. | F6: Higher ACV per account
A7: 3 | B7: European road freight forwarding | C7: The US cohort automates road brokerage; the EU cohort automates air and ocean. European road forwarding and charter brokerage - the Timocom world - sits between them, served by neither. | D7: GTM and ICP tab: no funded player names EU road forwarders as ICP. 5U AI already integrates Timocom, the dominant European road freight exchange - the entry point exists and is unmarketed. | E7: Cheapest adjacent expansion: same buyer type, same country, an integration already built. A 'Road Charter Worker' would face no direct funded competitor today. | F7: More addressable companies
A8: 4 | B8: Multilingual voice for EU forwarding | C8: Voice AI is mature in US brokerage (FleetWorks, Lanesurf, CloneOps, HappyRobot) and absent in EU forwarding, where phone traffic is multilingual and no US stack handles DACH/Benelux languages or carrier habits well. | D8: Feature matrix: voice is Yes across the US cohort, No or Unknown across the EU forwarding cohort. 5U AI claims the channel but demonstrates email first. | E8: A defensible second act rather than a first move - the US players set the quality bar, but none of them is tuned for European languages or forwarding call patterns. | F8: Higher ACV per account
A9: 5 | B9: TMS marketplace channel - 'certified agentic layer for CargoWise' | C9: Raft markets its CargoWise integration and wins deals through it, but no vendor owns the position of the certified agentic layer inside the WiseTech ecosystem. Distribution through the system of record beats direct sales in this market. | D9: GTM and ICP tab: partnership-as-distribution is the highest-leverage motion observed, and 5U AI is the only forward-deployed player running none of it despite having the WiseTech integration built. | E9: Fastest fix on the list: package and certify what already exists. The risk cuts both ways - deepening CargoWise dependency is also the platform risk in dossier section 11 - but the channel is open today. | F9: Distribution and trust
A10: 6 | B10: Decision-data benchmarking | C10: Every vendor logs decisions; none sells the aggregate back as market intelligence - quote-response benchmarks, lane-level exception rates, win-rate norms. Freightos monetises rate data but not operational-decision data. | D10: No competitor in the set offers an operational benchmarking product. 5U AI's Decision Layer is explicitly framed as its moat and already captures the raw material. | E10: A second product line with network effects: each customer makes the benchmark better, and the benchmark makes each sale easier. Requires the clause 10.3 data-rights question to be resolved cleanly first - the moat and the compliance risk are the same asset. | F10: Higher ACV per account
A11: 7 | B11: Regulated-AI positioning under the EU AI Act | C11: US entrants will face EU AI Act, GDPR and data-residency scrutiny when they cross the Atlantic. No vendor currently markets compliance as a product feature; the EU-native players treat it as legal boilerplate rather than a wedge. | D11: The competitor set's certifications are uniformly absent - no SOC 2 or ISO 27001 anywhere in the cohort. First to hold certifications plus documented AI-Act conformity wins enterprise procurement by default. | E11: Cheap insurance and sharp differentiation for the same spend: 5U AI needs the certifications anyway, and marketing them as 'the compliant choice' taxes every US rival's entry. | F11: Distribution and trust
A13: READING THE LIST AS A WHOLE
A14: Spaces 1 and 3 attack the ICP-arithmetic problem from the Market sizing tab (too few addressable companies). Spaces 2, 4 and 6 raise ACV per account - the other lever the sizing identified. Spaces 5 and 7 are distribution and trust fixes that cost little and compound.
A15: 5U AI's existing assets - the Timocom and WiseTech integrations, the Decision Layer, the EU incorporation - already sit at the mouth of five of the seven spaces. The whitespace is less about building new things than about marketing what is already built.
A16: Limitation: this analysis is derived from public positioning, so it finds gaps in what vendors SAY they do. A competitor could be quietly building in any of these spaces - customs and voice especially are obvious enough that they will not stay open long.

Sheet Unit economics
A1: 5U AI - unit economics (seller side)
A2: Does the rate card on the Pricing recommendation tab actually work for 5U AI? Gross margin per customer, delivery capacity, CAC/LTV and company break-even. Built entirely from assumptions (yellow) - 5U AI's real cost base is not public. Mirrors dossier section 16.
A4: 1. COST INPUTS
A5: Input | B5: Value | F5: Basis
A6: FDE fully loaded annual cost (EUR) | B6: 110000 | F6: Munich forward-deployed engineer: ~EUR 85-90k salary plus employer costs.
A7: Working weeks per FDE-year | B7: 46 | F7: Net of leave, holidays, internal work.
A8: FDE cost per week (EUR) | B8: =B6/B7 -> 2391.3043 | F8: Calculated
A9: FDE cost per day (EUR) | B9: =B6/(B7*5) -> 478.26087 | F9: Calculated
A10: Deployment FDE-weeks - first Worker | B10: 4 | F10: The ~4-week workshop-to-live cycle 5U AI describes.
A11: Deployment FDE-weeks - each additional Worker | B11: 2 | F11: Config and SOP work on an already-integrated account.
A12: FDE maintenance days per Worker per year | B12: 6 | F12: Portal changes, SOP updates, retraining. The self-healing claim reduces but does not remove this.
A13: Ops/CSM fully loaded annual cost (EUR) | B13: 90000 | F13: Munich Founding Ops profile.
A14: Accounts per Ops person at steady state | B14: 18 | F14: Weekly cadence for 6 weeks then monthly, per the Founding Ops job spec.
