Workbook

Sheet Read Me
B1: 5U AI — GTM Scenario & Stress-Test Model
B3: Built 30 Jul 2026 by Scaile research. Companion to 5U-AI-Research-Dossier.docx, 5U-AI-Competitor-Analysis.xlsx, 5U-AI-ICP-Report.docx and 5U-AI-MECE-Strategy.docx.
B5: How to use
B7: Every BLUE number is an editable input; YELLOW cells are the key levers. Everything black recalculates. To stress-test: change any blue cell on 'Assumptions' or the scenario levers on 'Scenarios' and watch ARR, EBITDA, break-even and cash flags update.
B9: Colour legend (standard model convention)
B11: Blue text = hardcoded input / lever. Black = formula. Green = link to another sheet. Yellow fill = key assumption you should challenge first.
B13: Structure (MECE)
B15: Scenarios S0–S5 are strategy choices (internal, mutually exclusive levers; S5 = combination). Stress shocks are environment cases (external), applied orthogonally to every scenario on 'Stress Tests'. Strategy × Environment covers the decision space without overlap.
B17: Source discipline
B19: Each assumption is tagged in column D of 'Assumptions': DOSSIER §n = sourced from the research dossier; ASSUMPTION = our estimate, not sourced — challenge these first. None of 5U AI's actual books are public; this tests the shape of the strategy, not audited financials.

Sheet Assumptions
A1: ASSUMPTIONS — edit blue cells
A2: Input | B2: Value | C2: Unit | D2: Source / note
A3: Beachhead pool (DACH+Benelux forwarders, 100–500 emp) | B3: 213 | C3: companies | D3: DOSSIER §13 (28% of EU base)
A4: Full ICP pool (EU+UK+US, 100–500 emp) | B4: 1479 | C4: companies | D4: DOSSIER §13 (4–6% of ~36,000)
A5: Self-serve tail pool reachable (DACH+BNL, <100 emp) | B5: 5320 | C5: companies | D5: Derived: ~19,000 EU × 28% — ASSUMPTION on reachability
A6: Road-freight pool addressable via Timocom | B6: 400 | C6: companies | D6: ASSUMPTION — not sourced in dossier; challenge first
A8: ACV — core (today) | B8: 60000 | C8: €/yr | D8: DOSSIER §13 SOM model
A9: ACV — expanded (customs + voice + deploy fees) | B9: 85000 | C9: €/yr | D9: DOSSIER §12 mature rate card €75–85k
A10: ACV — self-serve | B10: 6000 | C10: €/yr | D10: Benchmark: Cargofy ~US$5k sub-100 accounts
A11: ACV — road Worker | B11: 35000 | C11: €/yr | D11: ASSUMPTION — Launch-package price point
A13: Gross margin Y1 | B13: 0.44 | C13: % | D13: DOSSIER §16: 43–45% year 1
A14: Gross margin Y2 | B14: 0.55 | C14: % | D14: Interpolated — ASSUMPTION
A15: Gross margin Y3 (steady state) | B15: 0.65 | C15: % | D15: DOSSIER §16: 60–69% steady state
A16: Gross margin — self-serve (not separately modelled) | B16: 0.85 | C16: % | D16: ASSUMPTION; blended GM used for simplicity — conservative
... A38: Shock — capacity (FDE hiring shortfall) | B38: 0.5 | C38: % | D38: Case: Munich AI-talent market; forward-deployed bottleneck

Sheet Scenarios
A1: STRATEGY SCENARIOS — six MECE strategy cases, 3-year view
A2: Scenario | B2: S0 Beachhead only | C2: S1 + Partner channel | D2: S2 + ACV expansion | E2: S3 + Self-serve tail | F2: S4 + Road (Timocom) | G2: S5 Combined
B3: Status quo: founder-led, 213-co pool, €60k ACV | C3: CargoWise/Timocom channel lifts Y3 penetration | D3: Customs + voice + deploy fees raise ACV | E3: Base + product-led motion into <100-emp tail | F3: Base + Road Charter Worker via Timocom | G3: S1 levers + S2 ACV + S3 + S4 together
A5: LEVERS (blue = per-scenario input)
A6: Y3 core-ICP penetration | B6: 0.12 | C6: 0.2 | D6: 0.12 | E6: 0.12 | F6: 0.12 | G6: 0.2
A7: Core ACV used | B7: =Assumptions!$B$8 -> 60000 | C7: =Assumptions!$B$8 -> 60000 | D7: =Assumptions!$B$9 -> 85000 | E7: =Assumptions!$B$8 -> 60000 | F7: =Assumptions!$B$8 -> 60000 | G7: =Assumptions!$B$9 -> 85000
A8: Self-serve motion on? (0/1) | B8: 0 | C8: 0 | D8: 0 | E8: 1 | F8: 0 | G8: 1
A9: Road motion on? (0/1) | B9: 0 | C9: 0 | D9: 0 | E9: 0 | F9: 1 | G9: 1
A11: CUSTOMERS
A12: Forward-deployed customers Y1 | B12: =ROUND(MIN(Assumptions!$B$3*B$6*Assumptions!$B$18,Assumptions!$B$22*Assumptions!$B$21),0) -> 6 | C12: =ROUND(MIN(Assumptions!$B$3*C$6*Assumptions!$B$18,Assumptions!$B$22*Assumptions!$B$21),0) -> 11 | D12: =ROUND(MIN(Assumptions!$B$3*D$6*Assumptions!$B$18,Assumptions!$B$22*Assumptions!$B$21),0) -> 6 | E12: =ROUND(MIN(Assumptions!$B$3*E$6*Assumptions!$B$18,Assumptions!$B$22*Assumptions!$B$21),0) -> 6 | F12: =ROUND(MIN(Assumptions!$B$3*F$6*Assumptions!$B$18,Assumptions!$B$22*Assumptions!$B$21),0) -> 6 | G12: =ROUND(MIN(Assumptions!$B$3*G$6*Assumptions!$B$18,Assumptions!$B$22*Assumptions!$B$21),0) -> 11
A13: Forward-deployed customers Y2 | B13: =ROUND(MIN(Assumptions!$B$3*B$6*Assumptions!$B$19,Assumptions!$B$23*Assumptions!$B$21),0) -> 15 | C13: =ROUND(MIN(Assumptions!$B$3*C$6*Assumptions!$B$19,Assumptions!$B$23*Assumptions!$B$21),0) -> 26 | D13: =ROUND(MIN(Assumptions!$B$3*D$6*Assumptions!$B$19,Assumptions!$B$23*Assumptions!$B$21),0) -> 15 | E13: =ROUND(MIN(Assumptions!$B$3*E$6*Assumptions!$B$19,Assumptions!$B$23*Assumptions!$B$21),0) -> 15 | F13: =ROUND(MIN(Assumptions!$B$3*F$6*Assumptions!$B$19,Assumptions!$B$23*Assumptions!$B$21),0) -> 15 | G13: =ROUND(MIN(Assumptions!$B$3*G$6*Assumptions!$B$19,Assumptions!$B$23*Assumptions!$B$21),0) -> 26
A14: Forward-deployed customers Y3 | B14: =ROUND(MIN(Assumptions!$B$3*B$6,Assumptions!$B$24*Assumptions!$B$21),0) -> 26 | C14: =ROUND(MIN(Assumptions!$B$3*C$6,Assumptions!$B$24*Assumptions!$B$21),0) -> 43 | D14: =ROUND(MIN(Assumptions!$B$3*D$6,Assumptions!$B$24*Assumptions!$B$21),0) -> 26 | E14: =ROUND(MIN(Assumptions!$B$3*E$6,Assumptions!$B$24*Assumptions!$B$21),0) -> 26 | F14: =ROUND(MIN(Assumptions!$B$3*F$6,Assumptions!$B$24*Assumptions!$B$21),0) -> 26 | G14: =ROUND(MIN(Assumptions!$B$3*G$6,Assumptions!$B$24*Assumptions!$B$21),0) -> 43
A15: Self-serve customers Y3 | B15: =B8*ROUND(Assumptions!$B$5*Assumptions!$B$32,0) -> 0 | C15: =C8*ROUND(Assumptions!$B$5*Assumptions!$B$32,0) -> 0 | D15: =D8*ROUND(Assumptions!$B$5*Assumptions!$B$32,0) -> 0 | E15: =E8*ROUND(Assumptions!$B$5*Assumptions!$B$32,0) -> 80 | F15: =F8*ROUND(Assumptions!$B$5*Assumptions!$B$32,0) -> 0 | G15: =G8*ROUND(Assumptions!$B$5*Assumptions!$B$32,0) -> 80
A16: Road customers Y3 | B16: =B9*ROUND(Assumptions!$B$6*Assumptions!$B$33,0) -> 0 | C16: =C9*ROUND(Assumptions!$B$6*Assumptions!$B$33,0) -> 0 | D16: =D9*ROUND(Assumptions!$B$6*Assumptions!$B$33,0) -> 0 | E16: =E9*ROUND(Assumptions!$B$6*Assumptions!$B$33,0) -> 0 | F16: =F9*ROUND(Assumptions!$B$6*Assumptions!$B$33,0) -> 32 | G16: =G9*ROUND(Assumptions!$B$6*Assumptions!$B$33,0) -> 32
A17: FD potential Y3 (pre-capacity-cap) | B17: =Assumptions!$B$3*B$6 -> 25.56 | C17: =Assumptions!$B$3*C$6 -> 42.6 | D17: =Assumptions!$B$3*D$6 -> 25.56 | E17: =Assumptions!$B$3*E$6 -> 25.56 | F17: =Assumptions!$B$3*F$6 -> 25.56 | G17: =Assumptions!$B$3*G$6 -> 42.6
A18: FD capacity cap Y3 (FDEs × 10) | B18: =Assumptions!$B$24*Assumptions!$B$21 -> 60 | C18: =Assumptions!$B$24*Assumptions!$B$21 -> 60 | D18: =Assumptions!$B$24*Assumptions!$B$21 -> 60 | E18: =Assumptions!$B$24*Assumptions!$B$21 -> 60 | F18: =Assumptions!$B$24*Assumptions!$B$21 -> 60 | G18: =Assumptions!$B$24*Assumptions!$B$21 -> 60
A20: P&L
A21: ARR Y1 | B21: =B12*B$7 -> 360000 | C21: =C12*C$7 -> 660000 | D21: =D12*D$7 -> 510000 | E21: =E12*E$7 -> 360000 | F21: =F12*F$7 -> 360000 | G21: =G12*G$7 -> 935000
A22: ARR Y2 | B22: =B13*B$7+0.5*(B15*Assumptions!$B$10+B16*Assumptions!$B$11) -> 900000 | C22: =C13*C$7+0.5*(C15*Assumptions!$B$10+C16*Assumptions!$B$11) -> 1560000 | D22: =D13*D$7+0.5*(D15*Assumptions!$B$10+D16*Assumptions!$B$11) -> 1275000 | E22: =E13*E$7+0.5*(E15*Assumptions!$B$10+E16*Assumptions!$B$11) -> 1140000 | F22: =F13*F$7+0.5*(F15*Assumptions!$B$10+F16*Assumptions!$B$11) -> 1460000 | G22: =G13*G$7+0.5*(G15*Assumptions!$B$10+G16*Assumptions!$B$11) -> 3010000
A23: ARR Y3 | B23: =B14*B$7+B15*Assumptions!$B$10+B16*Assumptions!$B$11 -> 1560000 | C23: =C14*C$7+C15*Assumptions!$B$10+C16*Assumptions!$B$11 -> 2580000 | D23: =D14*D$7+D15*Assumptions!$B$10+D16*Assumptions!$B$11 -> 2210000 | E23: =E14*E$7+E15*Assumptions!$B$10+E16*Assumptions!$B$11 -> 2040000 | F23: =F14*F$7+F15*Assumptions!$B$10+F16*Assumptions!$B$11 -> 2680000 | G23: =G14*G$7+G15*Assumptions!$B$10+G16*Assumptions!$B$11 -> 5255000
A24: EBITDA Y1 | B24: =B21*Assumptions!$B$13-Assumptions!$B$26 -> -1241600 | C24: =C21*Assumptions!$B$13-Assumptions!$B$26 -> -1109600 | D24: =D21*Assumptions!$B$13-Assumptions!$B$26 -> -1175600 | E24: =E21*Assumptions!$B$13-Assumptions!$B$26 -> -1241600 | F24: =F21*Assumptions!$B$13-Assumptions!$B$26 -> -1241600 | G24: =G21*Assumptions!$B$13-Assumptions!$B$26 -> -988600
A25: EBITDA Y2 | B25: =B22*Assumptions!$B$14-Assumptions!$B$27 -> -1205000 | C25: =C22*Assumptions!$B$14-Assumptions!$B$27 -> -842000 | D25: =D22*Assumptions!$B$14-Assumptions!$B$27 -> -998750 | E25: =E22*Assumptions!$B$14-Assumptions!$B$27 -> -1073000 | F25: =F22*Assumptions!$B$14-Assumptions!$B$27 -> -897000 | G25: =G22*Assumptions!$B$14-Assumptions!$B$27 -> -44500
A26: EBITDA Y3 | B26: =B23*Assumptions!$B$15-Assumptions!$B$28 -> -886000 | C26: =C23*Assumptions!$B$15-Assumptions!$B$28 -> -223000 | D26: =D23*Assumptions!$B$15-Assumptions!$B$28 -> -463500 | E26: =E23*Assumptions!$B$15-Assumptions!$B$28 -> -574000 | F26: =F23*Assumptions!$B$15-Assumptions!$B$28 -> -158000 | G26: =G23*Assumptions!$B$15-Assumptions!$B$28 -> 1515750
A28: VERDICT
A29: Cash end of Y3 | B29: =Assumptions!$B$30+SUM(B24:B26) -> -382600 | C29: =Assumptions!$B$30+SUM(C24:C26) -> 775400 | D29: =Assumptions!$B$30+SUM(D24:D26) -> 312150 | E29: =Assumptions!$B$30+SUM(E24:E26) -> 61400 | F29: =Assumptions!$B$30+SUM(F24:F26) -> 653400 | G29: =Assumptions!$B$30+SUM(G24:G26) -> 3432650
A30: Break-even ARR (opex Y3 / GM Y3) | B30: =Assumptions!$B$28/Assumptions!$B$15 -> 2923076.9 | C30: =Assumptions!$B$28/Assumptions!$B$15 -> 2923076.9 | D30: =Assumptions!$B$28/Assumptions!$B$15 -> 2923076.9 | E30: =Assumptions!$B$28/Assumptions!$B$15 -> 2923076.9 | F30: =Assumptions!$B$28/Assumptions!$B$15 -> 2923076.9 | G30: =Assumptions!$B$28/Assumptions!$B$15 -> 2923076.9
A31: Break-even by Y3? | B31: =IF(B23>=B30,"Yes","No") -> No | C31: =IF(C23>=C30,"Yes","No") -> No | D31: =IF(D23>=D30,"Yes","No") -> No | E31: =IF(E23>=E30,"Yes","No") -> No | F31: =IF(F23>=F30,"Yes","No") -> No | G31: =IF(G23>=G30,"Yes","No") -> Yes
A32: Y3 ARR vs S0 | B32: =B23/$B$23 -> 1 | C32: =C23/$B$23 -> 1.6538462 | D32: =D23/$B$23 -> 1.4166667 | E32: =E23/$B$23 -> 1.3076923 | F32: =F23/$B$23 -> 1.7179487 | G32: =G23/$B$23 -> 3.3685897
A33: Funding verdict | B33: =IF(B29>0,"Funded through Y3","Raise needed") -> Raise needed | C33: =IF(C29>0,"Funded through Y3","Raise needed") -> Funded through Y3 | D33: =IF(D29>0,"Funded through Y3","Raise needed") -> Funded through Y3 | E33: =IF(E29>0,"Funded through Y3","Raise needed") -> Funded through Y3 | F33: =IF(F29>0,"Funded through Y3","Raise needed") -> Funded through Y3 | G33: =IF(G29>0,"Funded through Y3","Raise needed") -> Funded through Y3

Sheet Stress Tests
A1: STRESS TESTS — environment shocks × strategy scenarios
A3: Shock multipliers (derived from Assumptions rows 35–38)
A4: Shock case | B4: Demand × | C4: Churn × | D4: Price × | E4: Capacity ×
A5: Base (no shock) | B5: =1 -> 1 | C5: =1 -> 1 | D5: =1 -> 1 | E5: =1 -> 1
A6: Price pressure | B6: =1 -> 1 | C6: =1 -> 1 | D6: =1-Assumptions!$B$35 -> 0.8 | E6: =1 -> 1
A7: Demand loss | B7: =1-Assumptions!$B$36 -> 0.67 | C7: =1 -> 1 | D7: =1 -> 1 | E7: =1 -> 1
A8: Churn at renewal | B8: =1 -> 1 | C8: =1-Assumptions!$B$37 -> 0.85 | D8: =1 -> 1 | E8: =1 -> 1
A9: FDE hiring shortfall | B9: =1 -> 1 | C9: =1 -> 1 | D9: =1 -> 1 | E9: =1-Assumptions!$B$38 -> 0.5
A10: Combined downside | B10: =1-Assumptions!$B$36 -> 0.67 | C10: =1-Assumptions!$B$37 -> 0.85 | D10: =1-Assumptions!$B$35 -> 0.8 | E10: =1-Assumptions!$B$38 -> 0.5
A13: Y3 ARR under shock (€)
A14: Shock ↓ | B14: =Scenarios!B$2 -> S0 Beachhead only | C14: =Scenarios!C$2 -> S1 + Partner channel | D14: =Scenarios!D$2 -> S2 + ACV expansion | E14: =Scenarios!E$2 -> S3 + Self-serve tail | F14: =Scenarios!F$2 -> S4 + Road (Timocom) | G14: =Scenarios!G$2 -> S5 Combined
A15: =$A$5 -> Base (no shock) | B15: =MIN(Scenarios!B$17*$B$5*$C$5,Scenarios!B$18*$E$5)*Scenarios!B$7*$D$5+(Scenarios!B$15*Assumptions!$B$10+Scenarios!B$16*Assumptions!$B$11)*$B$5*$D$5 -> 1533600 | C15: =MIN(Scenarios!C$17*$B$5*$C$5,Scenarios!C$18*$E$5)*Scenarios!C$7*$D$5+(Scenarios!C$15*Assumptions!$B$10+Scenarios!C$16*Assumptions!$B$11)*$B$5*$D$5 -> 2556000 | D15: =MIN(Scenarios!D$17*$B$5*$C$5,Scenarios!D$18*$E$5)*Scenarios!D$7*$D$5+(Scenarios!D$15*Assumptions!$B$10+Scenarios!D$16*Assumptions!$B$11)*$B$5*$D$5 -> 2172600 | E15: =MIN(Scenarios!E$17*$B$5*$C$5,Scenarios!E$18*$E$5)*Scenarios!E$7*$D$5+(Scenarios!E$15*Assumptions!$B$10+Scenarios!E$16*Assumptions!$B$11)*$B$5*$D$5 -> 2013600 | F15: =MIN(Scenarios!F$17*$B$5*$C$5,Scenarios!F$18*$E$5)*Scenarios!F$7*$D$5+(Scenarios!F$15*Assumptions!$B$10+Scenarios!F$16*Assumptions!$B$11)*$B$5*$D$5 -> 2653600 | G15: =MIN(Scenarios!G$17*$B$5*$C$5,Scenarios!G$18*$E$5)*Scenarios!G$7*$D$5+(Scenarios!G$15*Assumptions!$B$10+Scenarios!G$16*Assumptions!$B$11)*$B$5*$D$5 -> 5221000
A16: =$A$6 -> Price pressure | B16: =MIN(Scenarios!B$17*$B$6*$C$6,Scenarios!B$18*$E$6)*Scenarios!B$7*$D$6+(Scenarios!B$15*Assumptions!$B$10+Scenarios!B$16*Assumptions!$B$11)*$B$6*$D$6 -> 1226880 | C16: =MIN(Scenarios!C$17*$B$6*$C$6,Scenarios!C$18*$E$6)*Scenarios!C$7*$D$6+(Scenarios!C$15*Assumptions!$B$10+Scenarios!C$16*Assumptions!$B$11)*$B$6*$D$6 -> 2044800 | D16: =MIN(Scenarios!D$17*$B$6*$C$6,Scenarios!D$18*$E$6)*Scenarios!D$7*$D$6+(Scenarios!D$15*Assumptions!$B$10+Scenarios!D$16*Assumptions!$B$11)*$B$6*$D$6 -> 1738080 | E16: =MIN(Scenarios!E$17*$B$6*$C$6,Scenarios!E$18*$E$6)*Scenarios!E$7*$D$6+(Scenarios!E$15*Assumptions!$B$10+Scenarios!E$16*Assumptions!$B$11)*$B$6*$D$6 -> 1610880 | F16: =MIN(Scenarios!F$17*$B$6*$C$6,Scenarios!F$18*$E$6)*Scenarios!F$7*$D$6+(Scenarios!F$15*Assumptions!$B$10+Scenarios!F$16*Assumptions!$B$11)*$B$6*$D$6 -> 2122880 | G16: =MIN(Scenarios!G$17*$B$6*$C$6,Scenarios!G$18*$E$6)*Scenarios!G$7*$D$6+(Scenarios!G$15*Assumptions!$B$10+Scenarios!G$16*Assumptions!$B$11)*$B$6*$D$6 -> 4176800
A17: =$A$7 -> Demand loss | B17: =MIN(Scenarios!B$17*$B$7*$C$7,Scenarios!B$18*$E$7)*Scenarios!B$7*$D$7+(Scenarios!B$15*Assumptions!$B$10+Scenarios!B$16*Assumptions!$B$11)*$B$7*$D$7 -> 1027512 | C17: =MIN(Scenarios!C$17*$B$7*$C$7,Scenarios!C$18*$E$7)*Scenarios!C$7*$D$7+(Scenarios!C$15*Assumptions!$B$10+Scenarios!C$16*Assumptions!$B$11)*$B$7*$D$7 -> 1712520 | D17: =MIN(Scenarios!D$17*$B$7*$C$7,Scenarios!D$18*$E$7)*Scenarios!D$7*$D$7+(Scenarios!D$15*Assumptions!$B$10+Scenarios!D$16*Assumptions!$B$11)*$B$7*$D$7 -> 1455642 | E17: =MIN(Scenarios!E$17*$B$7*$C$7,Scenarios!E$18*$E$7)*Scenarios!E$7*$D$7+(Scenarios!E$15*Assumptions!$B$10+Scenarios!E$16*Assumptions!$B$11)*$B$7*$D$7 -> 1349112 | F17: =MIN(Scenarios!F$17*$B$7*$C$7,Scenarios!F$18*$E$7)*Scenarios!F$7*$D$7+(Scenarios!F$15*Assumptions!$B$10+Scenarios!F$16*Assumptions!$B$11)*$B$7*$D$7 -> 1777912 | G17: =MIN(Scenarios!G$17*$B$7*$C$7,Scenarios!G$18*$E$7)*Scenarios!G$7*$D$7+(Scenarios!G$15*Assumptions!$B$10+Scenarios!G$16*Assumptions!$B$11)*$B$7*$D$7 -> 3498070
A18: =$A$8 -> Churn at renewal | B18: =MIN(Scenarios!B$17*$B$8*$C$8,Scenarios!B$18*$E$8)*Scenarios!B$7*$D$8+(Scenarios!B$15*Assumptions!$B$10+Scenarios!B$16*Assumptions!$B$11)*$B$8*$D$8 -> 1303560 | C18: =MIN(Scenarios!C$17*$B$8*$C$8,Scenarios!C$18*$E$8)*Scenarios!C$7*$D$8+(Scenarios!C$15*Assumptions!$B$10+Scenarios!C$16*Assumptions!$B$11)*$B$8*$D$8 -> 2172600 | D18: =MIN(Scenarios!D$17*$B$8*$C$8,Scenarios!D$18*$E$8)*Scenarios!D$7*$D$8+(Scenarios!D$15*Assumptions!$B$10+Scenarios!D$16*Assumptions!$B$11)*$B$8*$D$8 -> 1846710 | E18: =MIN(Scenarios!E$17*$B$8*$C$8,Scenarios!E$18*$E$8)*Scenarios!E$7*$D$8+(Scenarios!E$15*Assumptions!$B$10+Scenarios!E$16*Assumptions!$B$11)*$B$8*$D$8 -> 1783560 | F18: =MIN(Scenarios!F$17*$B$8*$C$8,Scenarios!F$18*$E$8)*Scenarios!F$7*$D$8+(Scenarios!F$15*Assumptions!$B$10+Scenarios!F$16*Assumptions!$B$11)*$B$8*$D$8 -> 2423560 | G18: =MIN(Scenarios!G$17*$B$8*$C$8,Scenarios!G$18*$E$8)*Scenarios!G$7*$D$8+(Scenarios!G$15*Assumptions!$B$10+Scenarios!G$16*Assumptions!$B$11)*$B$8*$D$8 -> 4677850
A19: =$A$9 -> FDE hiring shortfall | B19: =MIN(Scenarios!B$17*$B$9*$C$9,Scenarios!B$18*$E$9)*Scenarios!B$7*$D$9+(Scenarios!B$15*Assumptions!$B$10+Scenarios!B$16*Assumptions!$B$11)*$B$9*$D$9 -> 1533600 | C19: =MIN(Scenarios!C$17*$B$9*$C$9,Scenarios!C$18*$E$9)*Scenarios!C$7*$D$9+(Scenarios!C$15*Assumptions!$B$10+Scenarios!C$16*Assumptions!$B$11)*$B$9*$D$9 -> 1800000 | D19: =MIN(Scenarios!D$17*$B$9*$C$9,Scenarios!D$18*$E$9)*Scenarios!D$7*$D$9+(Scenarios!D$15*Assumptions!$B$10+Scenarios!D$16*Assumptions!$B$11)*$B$9*$D$9 -> 2172600 | E19: =MIN(Scenarios!E$17*$B$9*$C$9,Scenarios!E$18*$E$9)*Scenarios!E$7*$D$9+(Scenarios!E$15*Assumptions!$B$10+Scenarios!E$16*Assumptions!$B$11)*$B$9*$D$9 -> 2013600 | F19: =MIN(Scenarios!F$17*$B$9*$C$9,Scenarios!F$18*$E$9)*Scenarios!F$7*$D$9+(Scenarios!F$15*Assumptions!$B$10+Scenarios!F$16*Assumptions!$B$11)*$B$9*$D$9 -> 2653600 | G19: =MIN(Scenarios!G$17*$B$9*$C$9,Scenarios!G$18*$E$9)*Scenarios!G$7*$D$9+(Scenarios!G$15*Assumptions!$B$10+Scenarios!G$16*Assumptions!$B$11)*$B$9*$D$9 -> 4150000
A20: =$A$10 -> Combined downside | B20: =MIN(Scenarios!B$17*$B$10*$C$10,Scenarios!B$18*$E$10)*Scenarios!B$7*$D$10+(Scenarios!B$15*Assumptions!$B$10+Scenarios!B$16*Assumptions!$B$11)*$B$10*$D$10 -> 698708.16 | C20: =MIN(Scenarios!C$17*$B$10*$C$10,Scenarios!C$18*$E$10)*Scenarios!C$7*$D$10+(Scenarios!C$15*Assumptions!$B$10+Scenarios!C$16*Assumptions!$B$11)*$B$10*$D$10 -> 1164513.6 | D20: =MIN(Scenarios!D$17*$B$10*$C$10,Scenarios!D$18*$E$10)*Scenarios!D$7*$D$10+(Scenarios!D$15*Assumptions!$B$10+Scenarios!D$16*Assumptions!$B$11)*$B$10*$D$10 -> 989836.56 | E20: =MIN(Scenarios!E$17*$B$10*$C$10,Scenarios!E$18*$E$10)*Scenarios!E$7*$D$10+(Scenarios!E$15*Assumptions!$B$10+Scenarios!E$16*Assumptions!$B$11)*$B$10*$D$10 -> 955988.16 | F20: =MIN(Scenarios!F$17*$B$10*$C$10,Scenarios!F$18*$E$10)*Scenarios!F$7*$D$10+(Scenarios!F$15*Assumptions!$B$10+Scenarios!F$16*Assumptions!$B$11)*$B$10*$D$10 -> 1299028.2 | G20: =MIN(Scenarios!G$17*$B$10*$C$10,Scenarios!G$18*$E$10)*Scenarios!G$7*$D$10+(Scenarios!G$15*Assumptions!$B$10+Scenarios!G$16*Assumptions!$B$11)*$B$10*$D$10 -> 2507327.6
A23: Y3 EBITDA under shock (€) — negative = still burning at steady state
A24: Shock ↓ | B24: =Scenarios!B$2 -> S0 Beachhead only | C24: =Scenarios!C$2 -> S1 + Partner channel | D24: =Scenarios!D$2 -> S2 + ACV expansion | E24: =Scenarios!E$2 -> S3 + Self-serve tail | F24: =Scenarios!F$2 -> S4 + Road (Timocom) | G24: =Scenarios!G$2 -> S5 Combined
A25: =$A$5 -> Base (no shock) | B25: =B15*Assumptions!$B$15-Assumptions!$B$28 -> -903160 | C25: =C15*Assumptions!$B$15-Assumptions!$B$28 -> -238600 | D25: =D15*Assumptions!$B$15-Assumptions!$B$28 -> -487810 | E25: =E15*Assumptions!$B$15-Assumptions!$B$28 -> -591160 | F25: =F15*Assumptions!$B$15-Assumptions!$B$28 -> -175160 | G25: =G15*Assumptions!$B$15-Assumptions!$B$28 -> 1493650
A26: =$A$6 -> Price pressure | B26: =B16*Assumptions!$B$15-Assumptions!$B$28 -> -1102528 | C26: =C16*Assumptions!$B$15-Assumptions!$B$28 -> -570880 | D26: =D16*Assumptions!$B$15-Assumptions!$B$28 -> -770248 | E26: =E16*Assumptions!$B$15-Assumptions!$B$28 -> -852928 | F26: =F16*Assumptions!$B$15-Assumptions!$B$28 -> -520128 | G26: =G16*Assumptions!$B$15-Assumptions!$B$28 -> 814920
A27: =$A$7 -> Demand loss | B27: =B17*Assumptions!$B$15-Assumptions!$B$28 -> -1232117.2 | C27: =C17*Assumptions!$B$15-Assumptions!$B$28 -> -786862 | D27: =D17*Assumptions!$B$15-Assumptions!$B$28 -> -953832.7 | E27: =E17*Assumptions!$B$15-Assumptions!$B$28 -> -1023077.2 | F27: =F17*Assumptions!$B$15-Assumptions!$B$28 -> -744357.2 | G27: =G17*Assumptions!$B$15-Assumptions!$B$28 -> 373745.5
A28: =$A$8 -> Churn at renewal | B28: =B18*Assumptions!$B$15-Assumptions!$B$28 -> -1052686 | C28: =C18*Assumptions!$B$15-Assumptions!$B$28 -> -487810 | D28: =D18*Assumptions!$B$15-Assumptions!$B$28 -> -699638.5 | E28: =E18*Assumptions!$B$15-Assumptions!$B$28 -> -740686 | F28: =F18*Assumptions!$B$15-Assumptions!$B$28 -> -324686 | G28: =G18*Assumptions!$B$15-Assumptions!$B$28 -> 1140602.5
A29: =$A$9 -> FDE hiring shortfall | B29: =B19*Assumptions!$B$15-Assumptions!$B$28 -> -903160 | C29: =C19*Assumptions!$B$15-Assumptions!$B$28 -> -730000 | D29: =D19*Assumptions!$B$15-Assumptions!$B$28 -> -487810 | E29: =E19*Assumptions!$B$15-Assumptions!$B$28 -> -591160 | F29: =F19*Assumptions!$B$15-Assumptions!$B$28 -> -175160 | G29: =G19*Assumptions!$B$15-Assumptions!$B$28 -> 797500
A30: =$A$10 -> Combined downside | B30: =B20*Assumptions!$B$15-Assumptions!$B$28 -> -1445839.7 | C30: =C20*Assumptions!$B$15-Assumptions!$B$28 -> -1143066.2 | D30: =D20*Assumptions!$B$15-Assumptions!$B$28 -> -1256606.2 | E30: =E20*Assumptions!$B$15-Assumptions!$B$28 -> -1278607.7 | F30: =F20*Assumptions!$B$15-Assumptions!$B$28 -> -1055631.7 | G30: =G20*Assumptions!$B$15-Assumptions!$B$28 -> -270237.06
A33: Sensitivity — beachhead-only Y3 ARR (€): penetration × ACV
A34: Pen ↓ / ACV → | B34: 40000 | C34: 50000 | D34: 60000 | E34: 70000 | F34: 85000 | G34: 100000
A35: 0.06 | B35: =Assumptions!$B$3*$A35*B$34 -> 511200 | C35: =Assumptions!$B$3*$A35*C$34 -> 639000 | D35: =Assumptions!$B$3*$A35*D$34 -> 766800 | E35: =Assumptions!$B$3*$A35*E$34 -> 894600 | F35: =Assumptions!$B$3*$A35*F$34 -> 1086300 | G35: =Assumptions!$B$3*$A35*G$34 -> 1278000
A36: 0.09 | B36: =Assumptions!$B$3*$A36*B$34 -> 766800 | C36: =Assumptions!$B$3*$A36*C$34 -> 958500 | D36: =Assumptions!$B$3*$A36*D$34 -> 1150200 | E36: =Assumptions!$B$3*$A36*E$34 -> 1341900 | F36: =Assumptions!$B$3*$A36*F$34 -> 1629450 | G36: =Assumptions!$B$3*$A36*G$34 -> 1917000
A37: 0.12 | B37: =Assumptions!$B$3*$A37*B$34 -> 1022400 | C37: =Assumptions!$B$3*$A37*C$34 -> 1278000 | D37: =Assumptions!$B$3*$A37*D$34 -> 1533600 | E37: =Assumptions!$B$3*$A37*E$34 -> 1789200 | F37: =Assumptions!$B$3*$A37*F$34 -> 2172600 | G37: =Assumptions!$B$3*$A37*G$34 -> 2556000
A38: 0.15 | B38: =Assumptions!$B$3*$A38*B$34 -> 1278000 | C38: =Assumptions!$B$3*$A38*C$34 -> 1597500 | D38: =Assumptions!$B$3*$A38*D$34 -> 1917000 | E38: =Assumptions!$B$3*$A38*E$34 -> 2236500 | F38: =Assumptions!$B$3*$A38*F$34 -> 2715750 | G38: =Assumptions!$B$3*$A38*G$34 -> 3195000
A39: 0.18 | B39: =Assumptions!$B$3*$A39*B$34 -> 1533600 | C39: =Assumptions!$B$3*$A39*C$34 -> 1917000 | D39: =Assumptions!$B$3*$A39*D$34 -> 2300400 | E39: =Assumptions!$B$3*$A39*E$34 -> 2683800 | F39: =Assumptions!$B$3*$A39*F$34 -> 3258900 | G39: =Assumptions!$B$3*$A39*G$34 -> 3834000
A40: 0.21 | B40: =Assumptions!$B$3*$A40*B$34 -> 1789200 | C40: =Assumptions!$B$3*$A40*C$34 -> 2236500 | D40: =Assumptions!$B$3*$A40*D$34 -> 2683800 | E40: =Assumptions!$B$3*$A40*E$34 -> 3131100 | F40: =Assumptions!$B$3*$A40*F$34 -> 3802050 | G40: =Assumptions!$B$3*$A40*G$34 -> 4473000
A42: Break-even ARR benchmark (=Assumptions opex Y3 / GM Y3): | C42: =Assumptions!$B$28/Assumptions!$B$15 -> 2923076.9
A45: Break-even customers — opex × gross margin (at core ACV, Scenarios S0 column)
A46: Opex ↓ / GM → | B46: 0.45 | C46: 0.55 | D46: 0.65
A47: 1500000 | B47: =ROUND($A47/(Scenarios!$B$7*B$46),0) -> 56 | C47: =ROUND($A47/(Scenarios!$B$7*C$46),0) -> 45 | D47: =ROUND($A47/(Scenarios!$B$7*D$46),0) -> 38
A48: 1900000 | B48: =ROUND($A48/(Scenarios!$B$7*B$46),0) -> 70 | C48: =ROUND($A48/(Scenarios!$B$7*C$46),0) -> 58 | D48: =ROUND($A48/(Scenarios!$B$7*D$46),0) -> 49
A49: 2400000 | B49: =ROUND($A49/(Scenarios!$B$7*B$46),0) -> 89 | C49: =ROUND($A49/(Scenarios!$B$7*C$46),0) -> 73 | D49: =ROUND($A49/(Scenarios!$B$7*D$46),0) -> 62
A50: 3000000 | B50: =ROUND($A50/(Scenarios!$B$7*B$46),0) -> 111 | C50: =ROUND($A50/(Scenarios!$B$7*C$46),0) -> 91 | D50: =ROUND($A50/(Scenarios!$B$7*D$46),0) -> 77
...

Sheet MECE Map
A1: MECE STRATEGY MAP — see 5U-AI-MECE-Strategy.docx for the full system
A3: Level 1 — ARR drivers | B3: Customers (volume) | C3: × ACV (price) | D3: Constraint: FDE capacity (delivery)
A4: Level 2 — volume levers | B4: More penetration of core pool (S1) | C4: New pools: tail (S3), road (S4) | D4: Exhaustive: no other volume source exists
A5: Level 2 — price levers | B5: New Workers: customs, voice (S2) | C5: Monetise deployment (per-Worker fee) | D5: Exhaustive vs whitespace §15
A7: Segment (MECE) | B7: Primary channel (one owner each) | C7: Secondary support | D7: Never
A8: Core 100–500 forwarders, DACH+BNL | B8: Founder-led outbound, paid pilots | C8: References, comparison pages | D8: Broad paid marketing
A9: Core, in CargoWise ecosystem | B9: Certified CargoWise partner listing | C9: Raft-style integration content | D9: Competing head-on without the listing
A10: Road forwarders (Timocom users) | B10: Timocom marketplace | C10: Road Charter Worker launch content | D10: FDE-led selling at €35k ACV as the steady state (time-boxed discovery pilots excepted — see MECE doc)
A11: Sub-100 tail | B11: Product-led self-serve | C11: SEO/content only | D11: FDE deployment (uneconomic)
A12: 100–500 outside DACH+BNL | B12: Deferred — Y3+ decision gate | C12: — | D12: Premature geographic spread
